Workbook
Name Vendor: #REF!
Name Vendor: #REF!

Sheet 1 - Stakeholder Questionnaire
A1: AI Vendor Evaluation - Internal Stakeholder Questionnaire
B3: Third-Party Name: | C3: {name}
B4: Website: | C4: {website}
B5: Product/Service: | C5: {product/service}
B6: Instructions:
B7: Use the Comments field to add relevant details, including the name of the individual proving the response.
B8: For Internal Use | C8: Response | D8: Comments
A9: 1 | B9: Has a documented and approved business justification been established for the vendor to access, process, store, transmit, or manage PHI and/or PII? | C9: Yes
A10: 2 | B10: Has the healthcare business process, clinical workflow, or operational function supported by this vendor been clearly defined and documented? | C10: Yes
A11: 3 | B11: Will the vendor's services be accessible to patients, members, providers, workforce members, or other external users? | C11: Select one…
A12: 4 | B12: [IF YES] Have all required patient notices, consents, or authorizations been evaluated and implemented where required by HIPAA or applicable state privacy laws? | C12: Select one…
A13: 5 | B13: Does the proposed use align with HIPAA, HITECH, organizational privacy policies, security policies, and data governance requirements? | C13: Select one…
A14: 6 | B14: Are there any contractual, regulatory, legal, or customer obligations that restrict or prohibit the use of this vendor? | C14: Select one…
A15: 7 | B15: Do existing agreements, notices, consent forms, or Terms and Conditions require updates to address the vendor's access to or processing of PHI and PII? | C15: Select one…
A16: 8 | B16: Has the organization identified and defined the types of PHI and/or PII involved, and how the vendor will access, process, store, transmit, and protect the data? | C16: Select one…
A17: 9 | B17: [IF YES] Will PHI be processed within a dedicated healthcare environment, a shared environment, or a third-party cloud environment? | C17: Select one…
A18: 10 | B18: Can the vendor comply with HIPAA, HITECH, state privacy laws, and all applicable healthcare regulations? | C18: Select one…

Sheet 2 - Vendor Questionnaire
A1: AI Vendor Evaluation - Vendor Questionnaire
B3: Third-Party Name: | C3: {name}
B4: Website: | C4: {website}
B5: Product/Service: | C5: {product/service}
B6: Instructions:
B7: Use the Comments field to add relevant details.
B8: Domain | C8: Response | D8: Comments
A9: 1.0 | B9: General (Discovery)
A10: 1.1 | B10: Does your organization process, store, transmit, or access Protected Health Information (PHI)? | C10: Yes
A11: 1.2 | B11: [IF YES to 1.1 or 1.2] Describe how your service accesses, uses, stores, processes, transmits, and protects PHI. | C11: No
A12: 1.3 | B12: [IF YES to 1.1 or 1.2] Will AI-generated outputs influence patient care, treatment decisions, diagnoses, or clinical recommendations? | C12: Select one…
A13: 2 | B13: Data Privacy, Retention and Deletion
A14: 2.1 | B14: Has the vendor implemented controls to protect PHI and PII from unauthorized access, disclosure, alteration, misuse, or destruction? | C14: Yes
A15: 2.2 | B15: Do you provide privacy notices describing how PHI is collected, processed, stored, and disclosed? | C15: Partial (Explain)
A16: 2.3 | B16: Can PHI be excluded from optional processing, analytics, testing, or secondary use activities? | C16: Select one…
A17: 2.4 | B17: Does the vendor provide a documented process that allows authorized users or organizations to request exclusion of PHI and/or PII from optional processing activities, including AI model training, analytics, product improvement, or other secondary uses? | C17: Select one…
A18: 2.5 | B18: Has the vendor defined the service functionality that remains available when PHI processing restrictions, exclusions, or opt-out requirements are applied? | C18: Select one…
A19: 2.6 | B19: Will PHI be used for analytics, machine learning, product improvement, testing, research, or any purpose other than providing contracted services? | C19: Select one…
A20: 2.7 | B20: [IF YES] Can you provide evidence that PHI excluded from secondary use is not used for those purposes? | C20: Select one…
A21: 2.8 | B21: Does the service process PHI and PII that can be attributed to specific patients, users, or healthcare organizations? | C21: Select one…
A22: 2.9 | B22: Has the vendor established and documented retention periods for PHI and/or PII transmitted, processed, or stored through system integrations, APIs, or other interfaces? | C22: Select one…
A23: 2.10 | B23: Does your organization have a defined process and timeframe for secure deletion of PHI and PII, including deletion from backups and disaster recovery systems? | C23: Select one…
A24: 2.11 | B24: Can PHI and PII storage and processing be restricted to specific regions, countries, or jurisdictions? | C24: Select one…
A25: 2.12 | B25: Are documented data retention schedules reviewed and approved periodically to ensure continued compliance with legal, regulatory, and contractual requirements? | C25: Select one…
A26: 2.13 | B26: Can you provide confirmation or evidence when PHI and PII has been deleted following a customer request? | C26: Select one…
A27: 3.0 | B27: Model Training, Validation, and Maintenance
A28: 3.1 | B28: Has the vendor identified and documented all AI, machine learning, and foundational models used to provide the service, including model names, providers, and versions? | C28: Yes
A29: 3.2 | B29: Does the service rely on one or more Large Language Models (LLMs), machine learning models, predictive analytics models, generative AI models, or other AI technologies? | C29: Yes
A30: 3.3 | B30: Are the AI models used by the service proprietary, open-source, third-party provided, vendor-developed, or a combination thereof? | C30: Select one…
A31: 3.4 | B31: Is PHI, PII, ePHI, or customer healthcare data used to train, fine-tune, benchmark, evaluate, or improve the model? | C31: Select one…
A32: 3.5 | B32: Do you check the provenance of the data in the training set to ensure its use is permitted? | C32: Select one…
A33: 3.6 | B33: Is data used for model training, testing, or validation de-identified, aggregated, or anonymized where appropriate? | C33: Select one…
A34: 3.7 | B34: Does your model training process include human review or reinforcement learning from human feedback? | C34: Select one…
A35: 3.8 | B35: Do you publish a change log for the model? | C35: Select one…
A36: 3.9 | B36: Have you performed any independent audits or validation of AI model outputs? | C36: Select one…
A37: 3.10 | B37: [IF YES] Are you willing to share those results? | C37: Select one…
A38: 3.11 | B38: Is frequency of model validation and testing defined and documented? | C38: Select one…
A39: 3.12 | B39: Are AI-related incidents tracked, investigated, and documented? | C39: Select one…
A40: 4.0 | B40: AI & Information Security
A41: 4.1 | B41: Are penetration tests or other types of security assessments conducted on the model? | C41: Yes
...

Sheet Final Report
A1: AI Vendor Evaluation - Final Report
B3: Third-Party Name: | C3: {name}
B4: Website: | C4: {website}
B5: Product/Service: | C5: {product/service}
A6: Tips for Formatting and Archiving This Report:
A7: Ensure the content is visible in all cells: Highlight all cells, then navigate to Home > Format > Auto-Fit Row Height.
A8: Hide Excluded questions: Using the filter on Internal Stakeholders Responses cell, uncheck "EXCLUDED" to hide any questions excluded from all sections of the assessment.
A9: Print to PDF for archiving: Navigate to File > Print and select the available print-to-PDF option.
B11: I. Table of Contents
B12: II. Risk Analysis
B13: III. Internal Stakeholder Responses
B14: IV. Vendor Responses
B15: 1.0. General (Discovery)
B16: 2.0. Data Privacy, Retention, and Deletion
B17: 3.0. Model Training, Validation, and Maintenance
B18: 4.0. Information Security
B19: 5.0. Technology Integration
B20: 6.0. Nth Party Risk / Usage
B21: 7.0. Legal, Regulatory, and Compliance
B23: III. Internal Stakeholder Responses
A24: Following are the questions submitted to internal stakeholders, their responses, and additional comments.
B25: Question | C25: Responses | D25: Comments
A26: ='1 - Stakeholder Questionnaire'!A9 -> 1 | B26: ='1 - Stakeholder Questionnaire'!B9 -> Has a documented and approved business justification been established for the vendor to access, process, store, transmit, or manage PHI and/or PII? | C26: ='1 - Stakeholder Questionnaire'!C9 -> Yes | D26: =IF('1 - Stakeholder Questionnaire'!D9="","No comments provided",'1 - Stakeholder Questionnaire'!D9) -> No comments provided
A27: ='1 - Stakeholder Questionnaire'!A10 -> 2 | B27: ='1 - Stakeholder Questionnaire'!B10 -> Has the healthcare business process, clinical workflow, or operational function supported by this vendor been clearly defined and documented? | C27: ='1 - Stakeholder Questionnaire'!C10 -> Yes | D27: =IF('1 - Stakeholder Questionnaire'!D10="","No comments provided",'1 - Stakeholder Questionnaire'!D10) -> No comments provided
A28: ='1 - Stakeholder Questionnaire'!A11 -> 3 | B28: ='1 - Stakeholder Questionnaire'!B11 -> Will the vendor's services be accessible to patients, members, providers, workforce members, or other external users? | C28: ='1 - Stakeholder Questionnaire'!C11 -> Select one… | D28: =IF('1 - Stakeholder Questionnaire'!D11="","No comments provided",'1 - Stakeholder Questionnaire'!D11) -> No comments provided
A29: ='1 - Stakeholder Questionnaire'!A12 -> 4 | B29: ='1 - Stakeholder Questionnaire'!B12 -> [IF YES] Have all required patient notices, consents, or authorizations been evaluated and implemented where required by HIPAA or applicable state privacy laws? | C29: ='1 - Stakeholder Questionnaire'!C12 -> Select one… | D29: =IF('1 - Stakeholder Questionnaire'!D12="","No comments provided",'1 - Stakeholder Questionnaire'!D12) -> No comments provided
A30: ='1 - Stakeholder Questionnaire'!A13 -> 5 | B30: ='1 - Stakeholder Questionnaire'!B13 -> Does the proposed use align with HIPAA, HITECH, organizational privacy policies, security policies, and data governance requirements? | C30: ='1 - Stakeholder Questionnaire'!C13 -> Select one… | D30: =IF('1 - Stakeholder Questionnaire'!D13="","No comments provided",'1 - Stakeholder Questionnaire'!D13) -> No comments provided
A31: ='1 - Stakeholder Questionnaire'!A14 -> 6 | B31: ='1 - Stakeholder Questionnaire'!B14 -> Are there any contractual, regulatory, legal, or customer obligations that restrict or prohibit the use of this vendor? | C31: ='1 - Stakeholder Questionnaire'!C14 -> Select one… | D31: =IF('1 - Stakeholder Questionnaire'!D14="","No comments provided",'1 - Stakeholder Questionnaire'!D14) -> No comments provided
A32: ='1 - Stakeholder Questionnaire'!A15 -> 7 | B32: ='1 - Stakeholder Questionnaire'!B15 -> Do existing agreements, notices, consent forms, or Terms and Conditions require updates to address the vendor's access to or processing of PHI and PII? | C32: ='1 - Stakeholder Questionnaire'!C15 -> Select one… | D32: =IF('1 - Stakeholder Questionnaire'!D15="","No comments provided",'1 - Stakeholder Questionnaire'!D15) -> No comments provided
A33: ='1 - Stakeholder Questionnaire'!A16 -> 8 | B33: ='1 - Stakeholder Questionnaire'!B16 -> Has the organization identified and defined the types of PHI and/or PII involved, and how the vendor will access, process, store, transmit, and protect the data? | C33: ='1 - Stakeholder Questionnaire'!C16 -> Select one… | D33: =IF('1 - Stakeholder Questionnaire'!D16="","No comments provided",'1 - Stakeholder Questionnaire'!D16) -> No comments provided
A34: ='1 - Stakeholder Questionnaire'!A17 -> 9 | B34: ='1 - Stakeholder Questionnaire'!B17 -> [IF YES] Will PHI be processed within a dedicated healthcare environment, a shared environment, or a third-party cloud environment? | C34: ='1 - Stakeholder Questionnaire'!C17 -> Select one… | D34: =IF('1 - Stakeholder Questionnaire'!D17="","No comments provided",'1 - Stakeholder Questionnaire'!D17) -> No comments provided
A35: ='1 - Stakeholder Questionnaire'!A18 -> 10 | B35: ='1 - Stakeholder Questionnaire'!B18 -> Can the vendor comply with HIPAA, HITECH, state privacy laws, and all applicable healthcare regulations? | C35: ='1 - Stakeholder Questionnaire'!C18 -> Select one… | D35: =IF('1 - Stakeholder Questionnaire'!D18="","No comments provided",'1 - Stakeholder Questionnaire'!D18) -> No comments provided
B37: IV. Vendor Responses
A38: Following are the questions submitted to the vendor, the vendor's responses, and additional comments.
A39: ='2 - Vendor Questionnaire'!A9 -> 1.0 | B39: ='2 - Vendor Questionnaire'!B9 -> General (Discovery)
A40: ='2 - Vendor Questionnaire'!A10 -> 1.1 | B40: ='2 - Vendor Questionnaire'!B10 -> Does your organization process, store, transmit, or access Protected Health Information (PHI)? | C40: ='2 - Vendor Questionnaire'!C10 -> Yes | D40: =IF('2 - Vendor Questionnaire'!D10="","No comments provided",'2 - Vendor Questionnaire'!D10) -> No comments provided
A41: ='2 - Vendor Questionnaire'!A11 -> 1.2 | B41: ='2 - Vendor Questionnaire'!B11 -> [IF YES to 1.1 or 1.2] Describe how your service accesses, uses, stores, processes, transmits, and protects PHI. | C41: ='2 - Vendor Questionnaire'!C11 -> No | D41: =IF('2 - Vendor Questionnaire'!D11="","No comments provided",'2 - Vendor Questionnaire'!D11) -> No comments provided
A42: ='2 - Vendor Questionnaire'!A12 -> 1.3 | B42: ='2 - Vendor Questionnaire'!B12 -> [IF YES to 1.1 or 1.2] Will AI-generated outputs influence patient care, treatment decisions, diagnoses, or clinical recommendations? | C42: ='2 - Vendor Questionnaire'!C12 -> Select one… | D42: =IF('2 - Vendor Questionnaire'!D12="","No comments provided",'2 - Vendor Questionnaire'!D12) -> No comments provided
A43: ='2 - Vendor Questionnaire'!A13 -> 2 | B43: ='2 - Vendor Questionnaire'!B13 -> Data Privacy, Retention and Deletion | C43: ='2 - Vendor Questionnaire'!C13 -> 0 | D43: =IF('2 - Vendor Questionnaire'!D13="","No comments provided",'2 - Vendor Questionnaire'!D13) -> No comments provided
A44: ='2 - Vendor Questionnaire'!A14 -> 2.1 | B44: ='2 - Vendor Questionnaire'!B14 -> Has the vendor implemented controls to protect PHI and PII from unauthorized access, disclosure, alteration, misuse, or destruction? | C44: ='2 - Vendor Questionnaire'!C14 -> Yes | D44: =IF('2 - Vendor Questionnaire'!D14="","No comments provided",'2 - Vendor Questionnaire'!D14) -> No comments provided
...

Sheet Risk Score
A2: Purpose of this Sheet:
A3: This sheet calculates the score for each assessment category based on responses provided in the Stakeholder and Vendor Questionnaires.
A5: How Scores Are Calculated
A6: Yes = 1 and counted as part of the total
A7: No = 0 and counted as part of the total
A8: Partial = 0.5 and counted as part of the total
A9: N/A = Excluded from scoring and not counted in the total.
A10: The total score for each category is converted into a percentage and automatically transferred to the 'Reference Score' sheet.
A12: The Risk Score represents the combined percentage achieved across all assessment categories before category weightings are applied.
A13: This score may be higher than the Overall Risk Score shown in the Assessment Model sheet because the Overall Risk Score applies category-specific weightings to reflect the relative importance of each assessment area.
A16: Category | B16: Score | C16: Total | D16: Percentage Calculations
B17: Internal Stakeholder Responses
A18: 1 | B18: =IF('1 - Stakeholder Questionnaire'!C9="Yes",1,IF('1 - Stakeholder Questionnaire'!C9="No",0,IF('1 - Stakeholder Questionnaire'!C9="Partial (Explain)",0.5,""))) -> 1 | C18: =IF(B18<>"",1,"") -> 1 | D18: =(B28/C28) -> 1
A19: 2 | B19: =IF('1 - Stakeholder Questionnaire'!C10="Yes",1,IF('1 - Stakeholder Questionnaire'!C10="No",0,IF('1 - Stakeholder Questionnaire'!C10="Partial (Explain)",0.5,""))) -> 1 | C19: =IF(B19<>"",1,"") -> 1
A20: 3 | B20: =IF('1 - Stakeholder Questionnaire'!C11="Yes",1,IF('1 - Stakeholder Questionnaire'!C11="No",0,IF('1 - Stakeholder Questionnaire'!C11="Partial (Explain)",0.5,""))) | C20: =IF(B20<>"",1,"")
A21: 4 | B21: =IF('1 - Stakeholder Questionnaire'!C12="Yes",1,IF('1 - Stakeholder Questionnaire'!C12="No",0,IF('1 - Stakeholder Questionnaire'!C12="Partial (Explain)",0.5,""))) | C21: =IF(B21<>"",1,"")
A22: 5 | B22: =IF('1 - Stakeholder Questionnaire'!C13="Yes",1,IF('1 - Stakeholder Questionnaire'!C13="No",0,IF('1 - Stakeholder Questionnaire'!C13="Partial (Explain)",0.5,""))) | C22: =IF(B22<>"",1,"")
A23: 6 | B23: =IF('1 - Stakeholder Questionnaire'!C14="Yes",1,IF('1 - Stakeholder Questionnaire'!C14="No",0,IF('1 - Stakeholder Questionnaire'!C14="Partial (Explain)",0.5,""))) | C23: =IF(B23<>"",1,"")
A24: 7 | B24: =IF('1 - Stakeholder Questionnaire'!C15="Yes",1,IF('1 - Stakeholder Questionnaire'!C15="No",0,IF('1 - Stakeholder Questionnaire'!C15="Partial (Explain)",0.5,""))) | C24: =IF(B24<>"",1,"")
A25: 8 | B25: =IF('1 - Stakeholder Questionnaire'!C16="Yes",1,IF('1 - Stakeholder Questionnaire'!C16="No",0,IF('1 - Stakeholder Questionnaire'!C16="Partial (Explain)",0.5,""))) | C25: =IF(B25<>"",1,"")
A26: 9 | B26: =IF('1 - Stakeholder Questionnaire'!C17="Yes",1,IF('1 - Stakeholder Questionnaire'!C17="No",0,IF('1 - Stakeholder Questionnaire'!C17="Partial (Explain)",0.5,""))) | C26: =IF(B26<>"",1,"") | G26: Risk Score (Total Scored Percentage)
A27: 10 | B27: =IF('1 - Stakeholder Questionnaire'!C18="Yes",1,IF('1 - Stakeholder Questionnaire'!C18="No",0,IF('1 - Stakeholder Questionnaire'!C18="Partial (Explain)",0.5,""))) | C27: =IF(B27<>"",1,"") | M27: Low Risk
A28: Total | B28: =SUM(B18:B27) -> 2 | C28: =SUM(C18:C27) -> 2 | G28: =AVERAGE(D18,D32,D37,D53,D66) -> 0.75 | M28: Moderate Risk
M29: Medium Risk
B30: Vendor Responses | M30: High Risk
A31: 1 | B31: General (Discovery) | M31: Critical Risk
A32: 1.1 | B32: =IF('2 - Vendor Questionnaire'!C10="Yes",1,IF('2 - Vendor Questionnaire'!C10="No",0,IF('2 - Vendor Questionnaire'!C10="Partial (Explain)",0.5,""))) -> 1 | C32: =IF(B32<>"",1,"") -> 1 | D32: =(B35/C35) -> 0.5
A33: 1.2 | B33: =IF('2 - Vendor Questionnaire'!C11="Yes",1,IF('2 - Vendor Questionnaire'!C11="No",0,IF('2 - Vendor Questionnaire'!C11="Partial (Explain)",0.5,""))) -> 0 | C33: =IF(B33<>"",1,"") -> 1
A34: 1.3 | B34: =IF('2 - Vendor Questionnaire'!C12="Yes",1,IF('2 - Vendor Questionnaire'!C12="No",0,IF('2 - Vendor Questionnaire'!C12="Partial (Explain)",0.5,""))) | C34: =IF(B34<>"",1,"")
A35: Total | B35: =SUM(B32:B34) -> 1 | C35: =SUM(C32:C34) -> 2
A36: 2 | B36: Data Privacy, Retention and Deletion
A37: 2.1 | B37: =IF('2 - Vendor Questionnaire'!C14="Yes",1,IF('2 - Vendor Questionnaire'!C14="No",0,IF('2 - Vendor Questionnaire'!C14="Partial (Explain)",0.5,""))) -> 1 | C37: =IF(B37<>"",1,"") -> 1 | D37: =B51/C51 -> 0.75
A38: 2.2 | B38: =IF('2 - Vendor Questionnaire'!C15="Yes",1,IF('2 - Vendor Questionnaire'!C15="No",0,IF('2 - Vendor Questionnaire'!C15="Partial (Explain)",0.5,""))) -> 0.5 | C38: =IF(B38<>"",1,"") -> 1 | G38: Overall Risk Summary
A39: 2.3 | B39: =IF('2 - Vendor Questionnaire'!C16="Yes",1,IF('2 - Vendor Questionnaire'!C16="No",0,IF('2 - Vendor Questionnaire'!C16="Partial (Explain)",0.5,""))) | C39: =IF(B39<>"",1,"") | G39: Metric | I39: Result
A40: 2.4 | B40: =IF('2 - Vendor Questionnaire'!C17="Yes",1,IF('2 - Vendor Questionnaire'!C17="No",0,IF('2 - Vendor Questionnaire'!C17="Partial (Explain)",0.5,""))) | C40: =IF(B40<>"",1,"") | G40: Overall Risk Score (weighted) | I40: =SUM('Reference Score'!D2:D10) -> 0.775
A41: 2.5 | B41: =IF('2 - Vendor Questionnaire'!C18="Yes",1,IF('2 - Vendor Questionnaire'!C18="No",0,IF('2 - Vendor Questionnaire'!C18="Partial (Explain)",0.5,""))) | C41: =IF(B41<>"",1,"") | G41: Risk Rating (weighted) | I41: ='Reference Score'!B19 -> Medium Risk
A42: 2.6 | B42: =IF('2 - Vendor Questionnaire'!C19="Yes",1,IF('2 - Vendor Questionnaire'!C19="No",0,IF('2 - Vendor Questionnaire'!C19="Partial (Explain)",0.5,""))) | C42: =IF(B42<>"",1,"") | G42: Decision | I42: =IF(I41="Low Risk","Approved", IF(I41="Moderate Risk","Approved with Minor Conditions", IF(I41="Medium Risk","Risk Review Required", IF(I41="High Risk","Remediation Required", "Rejected")))) -> Risk Review Required
A43: 2.7 | B43: =IF('2 - Vendor Questionnaire'!C20="Yes",1,IF('2 - Vendor Questionnaire'!C20="No",0,IF('2 - Vendor Questionnaire'!C20="Partial (Explain)",0.5,""))) | C43: =IF(B43<>"",1,"") | G43: Assessor Comments | I43: =IF(I41="Low Risk","Vendor demonstrates strong security, privacy and compliance controls.", IF(I41="Moderate Risk","Minor gaps identified. Remediation should be tracked during onboarding.", IF(I41="Medium Risk","Several control deficiencies identified. Risk review recommended before approval.", IF(I41="High Risk","Significant security and compliance gaps identified. Remediation required prior to approval.", "Critical deficiencies identified. Vendor should not be approved until major issues are resolved.")))) -> Several control deficiencies identified. Risk review recommended before approval.
A44: 2.8 | B44: =IF('2 - Vendor Questionnaire'!C21="Yes",1,IF('2 - Vendor Questionnaire'!C21="No",0,IF('2 - Vendor Questionnaire'!C21="Partial (Explain)",0.5,""))) | C44: =IF(B44<>"",1,"")
A45: 2.9 | B45: =IF('2 - Vendor Questionnaire'!C22="Yes",1,IF('2 - Vendor Questionnaire'!C22="No",0,IF('2 - Vendor Questionnaire'!C22="Partial (Explain)",0.5,""))) | C45: =IF(B45<>"",1,"")
...

Sheet Reference Score
A1: Category | B1: Percentage | C1: Weight | D1: Weighted Score
A2: Stakeholder | B2: ='Risk Score'!D18 -> 1 | C2: 0.1 | D2: =B2*10% -> 0.1
A3: Genral | B3: ='Risk Score'!D32 -> 0.5 | C3: 0.05 | D3: =B3*5% -> 0.025
A4: Data Privacy | B4: ='Risk Score'!D37 -> 0.75 | C4: 0.2 | D4: =B4*20% -> 0.15
A5: Model Governance | B5: ='Risk Score'!D53 -> 1 | C5: 0.15 | D5: =B5*15% -> 0.15
A6: Information Security | B6: ='Risk Score'!D66 -> 0.5 | C6: 0.25 | D6: =B6*25% -> 0.125
A7: Technology Integration | B7: ='Risk Score'!D86 -> 1 | C7: 0.05 | D7: =B7*5% -> 0.05
A8: Third Party Risk | B8: ='Risk Score'!D92 -> 0.75 | C8: 0.1 | D8: =B8*10% -> 0.075
A9: Legal, Regulatory, and Compliance | B9: ='Risk Score'!D97 -> 1 | C9: 0.05 | D9: =B9*5% -> 0.05
A10: Access Management | B10: ='Risk Score'!D106 -> 1 | C10: 0.05 | D10: =B10*5% -> 0.05
A11: Overall risk score | B11: =SUM(D2:D10) -> 0.775
A13: Overall Score | B13: Risk Rating | C13: Decision
A14: 90% - 100% | B14: Low Risk | C14: Approved
A15: 80% - 89% | B15: Moderate Risk | C15: Approved with Minor Conditions
A16: 70% - 79% | B16: Medium Risk | C16: Risk Review Required
A17: 50% - 69% | B17: High Risk | C17: Remediation Required
A18: Below 50% | B18: Critical Risk | C18: Reject Vendor
A19: Risk Rating | B19: =IF(B11>=90%,"Low Risk", IF(B11>=80%,"Moderate Risk", IF(B11>=70%,"Medium Risk", IF(B11>=50%,"High Risk", "Critical Risk")))) -> Medium Risk

Sheet Assessment Controls
A1: Control ID | B1: Domain | C1: Control Statement | D1: Evidence Required | E1: Test Procedure | F1: Score (0-4) | G1: Notes
A2: CTRL-AI-001 | B2: Governance | C2: Use cases must be approved and risk classified | D2: Use case inventory, approval record | E2: Verify approvals
A3: CTRL-AI-010 | B3: Data Protection | C3: No training on client data without authorization | D3: Contract, architecture docs | E3: Inspect contract
A4: CTRL-AI-020 | B4: Model Risk | C4: Model transparency must be provided | D4: Model documentation | E4: Review docs
A5: CTRL-AI-030 | B5: Security | C5: Security testing required | D5: Pen test reports | E5: Validate reports
A6: CTRL-AI-040 | B6: Third Party | C6: Subprocessor disclosure required | D6: Vendor list | E6: Verify disclosure
A7: CTRL-AI-050 | B7: Legal | C7: Data ownership defined | D7: Contract terms | E7: Review contract
A8: CTRL-AI-060 | B8: Integration | C8: Secure API integration required | D8: API docs | E8: Inspect controls
A9: CTRL-AI-070 | B9: Monitoring | C9: Logging and monitoring enabled | D9: Logs, SIEM exports | E9: Review logs

Sheet Scoring Model
A1: Score | B1: Definition
A2: 0 | B2: Not implemented
A3: 1 | B3: Partially implemented
A4: 2 | B4: Implemented (no evidence)
A5: 3 | B5: Implemented with evidence
A6: 4 | B6: Validated

Sheet Decision Thresholds
A1: Score Range | B1: Decision | C1: Action
A2: >=85% | B2: Approve | C2: Standard monitoring
A3: 70-84% | B3: Conditional | C3: Remediation required
A4: 50-69% | B4: High Risk | C4: Senior approval
A5: <50% | B5: Reject | C5: Do not onboard

Sheet Scorecard
A1: Metric | B1: Value
A2: Total Controls | B2: -1
A3: Average Score | B3: #DIV/0!
A4: Weighted Score % | B4: #DIV/0!
A5: Risk Tier | B5: Enter Low/Moderate/High
A6: Final Score | B6: =B4 -> #DIV/0!
A7: Decision | B7: =IF(B6>=85,"APPROVE",IF(B6>=70,"CONDITIONAL",IF(B6>=50,"HIGH RISK","REJECT"))) -> #DIV/0!
A9: Business Owner Sign-Off
A10: Name:
A11: Title:
A12: Decision: | B12: Approve / Conditional / Reject
A13: Risk Acceptance Required (Y/N):
A14: Signature:
A15: Date:
